----------------------------
----------------------------
Log: 2018-01-11 13:59:19.102000

Begin process:
     Process started at 2018-01-11 13:59:19.102000

PYTHON ERRORS:
Traceback info:
  File "TCHD_arcOffice.py", line 114, in <module>
    for search_row in search_cur:

Error Info:
A column was specified that does not exist.
Failed @2018-01-11 13:59:19.102000----------------------------
----------------------------
Log: 2018-01-11 14:15:27.099981

Begin process:
     Process started at 2018-01-11 14:15:27.100984

     Completed successfully in 0:00:06.315636

----------------------------
----------------------------
Log: 2018-01-23 17:09:23.140975

Begin process:
     Process started at 2018-01-23 17:09:23.141977

     Completed successfully in 0:00:20.845575

----------------------------
----------------------------
Log: 2018-02-13 17:20:15.437000

Begin process:
     Process started at 2018-02-13 17:20:15.437000

PYTHON ERRORS:
Traceback info:
  File "testingtesting.py", line 111, in <module>
    arcpy.Delete_management("GeocodedAddresses")

Error Info:
ERROR 000464: Cannot get exclusive schema lock.  Either being edited or in use by another application.
Failed to execute (Delete).

Failed @2018-02-13 17:20:15.437000----------------------------
----------------------------
Log: 2018-02-13 17:20:51.513000

Begin process:
     Process started at 2018-02-13 17:20:51.513000

     Completed successfully in 0:00:26.608000

----------------------------
----------------------------
Log: 2018-02-13 17:45:34.965761

Begin process:
     Process started at 2018-02-13 17:45:34.965761

PYTHON ERRORS:
Traceback info:
  File "D:/Projects/TCHD/TCHD_spyder/testingtesting.py", line 128, in <module>
    for search_row in search_cur:

Error Info:
A column was specified that does not exist.
Failed @2018-02-13 17:45:34.965761----------------------------
----------------------------
Log: 2018-02-13 17:46:44.883000

Begin process:
     Process started at 2018-02-13 17:46:44.883000

     Completed successfully in 0:00:16.653000

----------------------------
----------------------------
Log: 2018-02-20 15:14:28.612000

Begin process:
     Process started at 2018-02-20 15:14:28.612000

PYTHON ERRORS:
Traceback info:
  File "TCHD_facility_violations_max.py", line 157, in <module>
    deleteeditfields(facilitiesstaging)

Error Info:
Failed to execute. Parameters are not valid.
ERROR 000732: Input Table: Dataset Database Connections\SA_srvarcgis.sde\FACILITIES does not exist or is not supported
Failed to execute (DeleteField).

Failed @2018-02-20 15:14:28.612000----------------------------
----------------------------
Log: 2018-02-20 15:15:52.182000

Begin process:
     Process started at 2018-02-20 15:15:52.182000

     Completed successfully in 0:00:20.429000

